<?xml version="1.0" encoding="utf-8"?>
<!--
  UR5e Pinocchio model for Lab 6.

  Kinematics match the MuJoCo Menagerie UR5e arm (same chain as Lab 3).
  The world_joint includes a 180-degree Z rotation to match the Menagerie
  base body quat="0 0 0 -1".  No gripper payload — bare UR5e arm.
-->
<robot name="ur5e_lab6">

  <link name="world"/>

  <link name="base_link">
    <inertial>
      <mass value="4.0"/>
      <origin rpy="0 0 0" xyz="0 0 0"/>
      <inertia ixx="0.00443333156" ixy="0.0" ixz="0.0"
               iyy="0.00443333156" iyz="0.0" izz="0.0072"/>
    </inertial>
  </link>

  <link name="shoulder_link">
    <inertial>
      <mass value="3.7"/>
      <origin rpy="0 0 0" xyz="0 0 0"/>
      <inertia ixx="0.0102675" ixy="0.0" ixz="0.0"
               iyy="0.0102675" iyz="0.0" izz="0.00666"/>
    </inertial>
  </link>

  <link name="upper_arm_link">
    <inertial>
      <mass value="8.393"/>
      <origin rpy="0 0 0" xyz="0 0 0.2125"/>
      <inertia ixx="0.133886" ixy="0.0" ixz="0.0"
               iyy="0.133886" iyz="0.0" izz="0.0151074"/>
    </inertial>
  </link>

  <link name="forearm_link">
    <inertial>
      <mass value="2.275"/>
      <origin rpy="0 0 0" xyz="0 0 0.196"/>
      <inertia ixx="0.0311796" ixy="0.0" ixz="0.0"
               iyy="0.0311796" iyz="0.0" izz="0.004095"/>
    </inertial>
  </link>

  <link name="wrist_1_link">
    <inertial>
      <mass value="1.219"/>
      <origin rpy="0 0 0" xyz="0 0.127 0"/>
      <inertia ixx="0.0025599" ixy="0.0" ixz="0.0"
               iyy="0.0025599" iyz="0.0" izz="0.0021942"/>
    </inertial>
  </link>

  <link name="wrist_2_link">
    <inertial>
      <mass value="1.219"/>
      <origin rpy="0 0 0" xyz="0 0 0.1"/>
      <inertia ixx="0.0025599" ixy="0.0" ixz="0.0"
               iyy="0.0025599" iyz="0.0" izz="0.0021942"/>
    </inertial>
  </link>

  <link name="wrist_3_link">
    <inertial>
      <mass value="0.1889"/>
      <origin rpy="0 0 0" xyz="0 0.0771683 0"/>
      <inertia ixx="0.000132134" ixy="0.0" ixz="0.0"
               iyy="9.90863e-05" iyz="0.0" izz="9.90863e-05"/>
    </inertial>
  </link>

  <link name="ee_link">
    <inertial>
      <mass value="0.1"/>
      <origin rpy="0 0 0" xyz="0 0 0"/>
      <inertia ixx="1e-6" ixy="0" ixz="0" iyy="1e-6" iyz="0" izz="1e-6"/>
    </inertial>
  </link>

  <!-- ===== Joints ===== -->

  <joint name="world_joint" type="fixed">
    <parent link="world"/>
    <child link="base_link"/>
    <origin rpy="0 0 3.14159265358979" xyz="0 0 0"/>
  </joint>

  <joint name="shoulder_pan_joint" type="revolute">
    <parent link="base_link"/>
    <child link="shoulder_link"/>
    <origin rpy="0 0 0" xyz="0 0 0.163"/>
    <axis xyz="0 0 1"/>
    <limit effort="150.0" lower="-6.28318530718" upper="6.28318530718" velocity="3.14"/>
  </joint>

  <joint name="shoulder_lift_joint" type="revolute">
    <parent link="shoulder_link"/>
    <child link="upper_arm_link"/>
    <origin rpy="0 1.5707963267948966 0" xyz="0 0.138 0"/>
    <axis xyz="0 1 0"/>
    <limit effort="150.0" lower="-6.28318530718" upper="6.28318530718" velocity="3.14"/>
  </joint>

  <joint name="elbow_joint" type="revolute">
    <parent link="upper_arm_link"/>
    <child link="forearm_link"/>
    <origin rpy="0 0 0" xyz="0 -0.131 0.425"/>
    <axis xyz="0 1 0"/>
    <limit effort="150.0" lower="-3.14159265359" upper="3.14159265359" velocity="3.14"/>
  </joint>

  <joint name="wrist_1_joint" type="revolute">
    <parent link="forearm_link"/>
    <child link="wrist_1_link"/>
    <origin rpy="0 1.5707963267948966 0" xyz="0 0 0.392"/>
    <axis xyz="0 1 0"/>
    <limit effort="28.0" lower="-6.28318530718" upper="6.28318530718" velocity="6.28"/>
  </joint>

  <joint name="wrist_2_joint" type="revolute">
    <parent link="wrist_1_link"/>
    <child link="wrist_2_link"/>
    <origin rpy="0 0 0" xyz="0 0.127 0"/>
    <axis xyz="0 0 1"/>
    <limit effort="28.0" lower="-6.28318530718" upper="6.28318530718" velocity="6.28"/>
  </joint>

  <joint name="wrist_3_joint" type="revolute">
    <parent link="wrist_2_link"/>
    <child link="wrist_3_link"/>
    <origin rpy="0 0 0" xyz="0 0 0.1"/>
    <axis xyz="0 1 0"/>
    <limit effort="28.0" lower="-6.28318530718" upper="6.28318530718" velocity="6.28"/>
  </joint>

  <joint name="ee_fixed_joint" type="fixed">
    <parent link="wrist_3_link"/>
    <child link="ee_link"/>
    <origin rpy="-1.5707963267948966 0 0" xyz="0 0.1 0"/>
  </joint>

</robot>
